Workbook
Name EMP: Table1[]

Sheet piovt table
A3: STATUS | B3: TOTAL BASIC SALARY | E3: Row Labels | F3: Sum of HOUSING (25%) | I3: Row Labels | J3: Sum of MEDICAL (10%) | M3: Row Labels | N3: Sum of TRANSPORT(12.5%) | P3: cLERK | Q3: Sum of WELFARE (5.7%) | S3: cLERK | T3: Sum of BONUS (3.2%) | V3: cLERK | W3: Sum of GROSS EARN | Y3: cLERK | Z3: Sum of TAX PER MON (1.25%) | AB3: cLERK | AC3: Sum of NET EARN | AE3: cLERK | AF3: Sum of ANNUAL NET | AH3: cLERK | AI3: Sum of ANNUAL TAX | AK3: cLERK | AL3: Sum of ACTUAL TAX | AN3: cLERK | AO3: Sum of ACTUAL NET
A4: CLERK | B4: 2715000 | E4: CLERK | F4: 678750 | I4: CLERK | J4: 271500 | M4: CLERK | N4: 339375 | P4: CLERK | Q4: 154755 | S4: CLERK | T4: 86880 | V4: CLERK | W4: 4246260 | Y4: CLERK | Z4: 53078.25 | AB4: CLERK | AC4: 4193181.8 | AE4: CLERK | AF4: 50318181 | AH4: CLERK | AI4: 636939 | AK4: CLERK | AL4: 7547727.2 | AN4: CLERK | AO4: 42770454
A5: JUNIOR | B5: 4205700 | E5: JUNIOR | F5: 1051425 | I5: JUNIOR | J5: 420570 | M5: JUNIOR | N5: 525712.5 | P5: JUNIOR | Q5: 239724.9 | S5: JUNIOR | T5: 134582.4 | V5: JUNIOR | W5: 6577714.8 | Y5: JUNIOR | Z5: 82221.435 | AB5: JUNIOR | AC5: 6495493.4 | AE5: JUNIOR | AF5: 77945920 | AH5: JUNIOR | AI5: 986657.22 | AK5: JUNIOR | AL5: 14432978 | AN5: JUNIOR | AO5: 63512942
A6: SENIOR | B6: 5921679 | E6: SENIOR | F6: 1480419.8 | I6: SENIOR | J6: 592167.9 | M6: SENIOR | N6: 740209.88 | P6: SENIOR | Q6: 337535.7 | S6: SENIOR | T6: 189493.73 | V6: SENIOR | W6: 9261506 | Y6: SENIOR | Z6: 115768.82 | AB6: SENIOR | AC6: 9145737.1 | AE6: SENIOR | AF6: 1.0974885e+08 | AH6: SENIOR | AI6: 1389225.9 | AK6: SENIOR | AL6: 27437211 | AN6: SENIOR | AO6: 82311634
A7: Grand Total | B7: 12842379 | E7: Grand Total | F7: 3210594.8 | I7: Grand Total | J7: 1284237.9 | M7: Grand Total | N7: 1605297.4 | P7: Grand Total | Q7: 732015.6 | S7: Grand Total | T7: 410956.13 | V7: Grand Total | W7: 20085481 | Y7: Grand Total | Z7: 251068.51 | AB7: Grand Total | AC7: 19834412 | AE7: Grand Total | AF7: 2.3801295e+08 | AH7: Grand Total | AI7: 3012822.1 | AK7: Grand Total | AL7: 49417916 | AN7: Grand Total | AO7: 1.8859503e+08
A12: LEVEL | B12: TOTAL BASIC SALARY | E12: Row Labels | F12: Sum of HOUSING (25%) | I12: grand Total | J12: Sum of MEDICAL (10%) | M12: grand Total | N12: Sum of TRANSPORT(12.5%) | P12: grand Total | Q12: Sum of WELFARE (5.7%) | S12: grand Total | T12: Sum of BONUS (3.2%) | V12: grand Total | W12: Sum of GROSS EARN | Y12: grand Total | Z12: Sum of TAX PER MON (1.25%) | AB12: grand Total | AC12: Sum of NET EARN | AE12: grand Total | AF12: Sum of ANNUAL NET | AH12: grand Total | AI12: Sum of ANNUAL NET | AJ12: Sum of ANNUAL TAX | AK12: Sum of ACTUAL TAX | AL12: Sum of ACTUAL NET
A13: 1 | B13: 350000 | E13: 1 | F13: 87500 | I13: 1 | J13: 35000 | M13: 1 | N13: 43750 | P13: 1 | Q13: 19950 | S13: 1 | T13: 11200 | V13: 1 | W13: 547400 | Y13: 1 | Z13: 6842.5 | AB13: 1 | AC13: 540557.5 | AE13: 1 | AF13: 6486690 | AH13: 1 | AI13: 6486690 | AJ13: 82110 | AK13: 973003.5 | AL13: 5513686.5
A14: 2 | B14: 450000 | E14: 2 | F14: 112500 | I14: 2 | J14: 45000 | M14: 2 | N14: 56250 | P14: 2 | Q14: 25650 | S14: 2 | T14: 14400 | V14: 2 | W14: 703800 | Y14: 2 | Z14: 8797.5 | AB14: 2 | AC14: 695002.5 | AE14: 2 | AF14: 8340030 | AH14: 2 | AI14: 8340030 | AJ14: 105570 | AK14: 1251004.5 | AL14: 7089025.5
A15: 3 | B15: 480000 | E15: 3 | F15: 120000 | I15: 3 | J15: 48000 | M15: 3 | N15: 60000 | P15: 3 | Q15: 27360 | S15: 3 | T15: 15360 | V15: 3 | W15: 750720 | Y15: 3 | Z15: 9384 | AB15: 3 | AC15: 741336 | AE15: 3 | AF15: 8896032 | AH15: 3 | AI15: 8896032 | AJ15: 112608 | AK15: 1334404.8 | AL15: 7561627.2
A16: 4 | B16: 510000 | E16: 4 | F16: 127500 | I16: 4 | J16: 51000 | M16: 4 | N16: 63750 | P16: 4 | Q16: 29070 | S16: 4 | T16: 16320 | V16: 4 | W16: 797640 | Y16: 4 | Z16: 9970.5 | AB16: 4 | AC16: 787669.5 | AE16: 4 | AF16: 9452034 | AH16: 4 | AI16: 9452034 | AJ16: 119646 | AK16: 1417805.1 | AL16: 8034228.9
A17: 5 | B17: 450000 | E17: 5 | F17: 112500 | I17: 5 | J17: 45000 | M17: 5 | N17: 56250 | P17: 5 | Q17: 25650 | S17: 5 | T17: 14400 | V17: 5 | W17: 703800 | Y17: 5 | Z17: 8797.5 | AB17: 5 | AC17: 695002.5 | AE17: 5 | AF17: 8340030 | AH17: 5 | AI17: 8340030 | AJ17: 105570 | AK17: 1251004.5 | AL17: 7089025.5
A18: 6 | B18: 475000 | E18: 6 | F18: 118750 | I18: 6 | J18: 47500 | M18: 6 | N18: 59375 | P18: 6 | Q18: 27075 | S18: 6 | T18: 15200 | V18: 6 | W18: 742900 | Y18: 6 | Z18: 9286.25 | AB18: 6 | AC18: 733613.75 | AE18: 6 | AF18: 8803365 | AH18: 6 | AI18: 8803365 | AJ18: 111435 | AK18: 1320504.8 | AL18: 7482860.2
A19: 7 | B19: 514500 | E19: 7 | F19: 128625 | I19: 7 | J19: 51450 | M19: 7 | N19: 64312.5 | P19: 7 | Q19: 29326.5 | S19: 7 | T19: 16464 | V19: 7 | W19: 804678 | Y19: 7 | Z19: 10058.475 | AB19: 7 | AC19: 794619.52 | AE19: 7 | AF19: 9535434.3 | AH19: 7 | AI19: 9535434.3 | AJ19: 120701.7 | AK19: 1430315.1 | AL19: 8105119.2
A20: 8 | B20: 677400 | E20: 8 | F20: 169350 | I20: 8 | J20: 67740 | M20: 8 | N20: 84675 | P20: 8 | Q20: 38611.8 | S20: 8 | T20: 21676.8 | V20: 8 | W20: 1059453.6 | Y20: 8 | Z20: 13243.17 | AB20: 8 | AC20: 1046210.4 | AE20: 8 | AF20: 12554525 | AH20: 8 | AI20: 12554525 | AJ20: 158918.04 | AK20: 1883178.8 | AL20: 10671346
A21: 9 | B21: 737400 | C21: GETPIVOTDATA("Count of BASIC SALARY",$A$48,"STATUS","CLERK") | E21: 9 | F21: 184350 | I21: 9 | J21: 73740 | M21: 9 | N21: 92175 | P21: 9 | Q21: 42031.8 | S21: 9 | T21: 23596.8 | V21: 9 | W21: 1153293.6 | Y21: 9 | Z21: 14416.17 | AB21: 9 | AC21: 1138877.4 | AE21: 9 | AF21: 13666529 | AH21: 9 | AI21: 13666529 | AJ21: 172994.04 | AK21: 2049979.4 | AL21: 11616550
A22: 10 | B22: 797400 | E22: 10 | F22: 199350 | I22: 10 | J22: 79740 | M22: 10 | N22: 99675 | P22: 10 | Q22: 45451.8 | S22: 10 | T22: 25516.8 | V22: 10 | W22: 1247133.6 | Y22: 10 | Z22: 15589.17 | AB22: 10 | AC22: 1231544.4 | AE22: 10 | AF22: 14778533 | AH22: 10 | AI22: 14778533 | AJ22: 187070.04 | AK22: 2216780 | AL22: 12561753
A23: 11 | B23: 714500 | E23: 11 | F23: 178625 | I23: 11 | J23: 71450 | M23: 11 | N23: 89312.5 | P23: 11 | Q23: 40726.5 | S23: 11 | T23: 22864 | V23: 11 | W23: 1117478 | Y23: 11 | Z23: 13968.475 | AB23: 11 | AC23: 1103509.5 | AE23: 11 | AF23: 13242114 | AH23: 11 | AI23: 13242114 | AJ23: 167621.7 | AK23: 3310528.6 | AL23: 9931585.7
A24: 12 | B24: 764500 | E24: 12 | F24: 191125 | I24: 12 | J24: 76450 | M24: 12 | N24: 95562.5 | P24: 12 | Q24: 43576.5 | S24: 12 | T24: 24464 | V24: 12 | W24: 1195678 | Y24: 12 | Z24: 14945.975 | AB24: 12 | AC24: 1180732 | AE24: 12 | AF24: 14168784 | AH24: 12 | AI24: 14168784 | AJ24: 179351.7 | AK24: 3542196.1 | AL24: 10626588
A25: 13 | B25: 1058841 | E25: 13 | F25: 264710.25 | I25: 13 | J25: 105884.1 | M25: 13 | N25: 132355.12 | P25: 13 | Q25: 60353.937 | S25: 13 | T25: 33882.912 | V25: 13 | W25: 1656027.3 | Y25: 13 | Z25: 20700.342 | AB25: 13 | AC25: 1635327 | AE25: 13 | AF25: 19623924 | AH25: 13 | AI25: 19623924 | AJ25: 248404.1 | AK25: 4905980.9 | AL25: 14717943
A26: 14 | B26: 1163841 | E26: 14 | F26: 290960.25 | I26: 14 | J26: 116384.1 | M26: 14 | N26: 145480.12 | P26: 14 | Q26: 66338.937 | S26: 14 | T26: 37242.912 | V26: 14 | W26: 1820247.3 | Y26: 14 | Z26: 22753.092 | AB26: 14 | AC26: 1797494.2 | AE26: 14 | AF26: 21569931 | AH26: 14 | AI26: 21569931 | AJ26: 273037.1 | AK26: 5392482.7 | AL26: 16177448
A27: 15 | B27: 1268841 | E27: 15 | F27: 317210.25 | I27: 15 | J27: 126884.1 | M27: 15 | N27: 158605.12 | P27: 15 | Q27: 72323.937 | S27: 15 | T27: 40602.912 | V27: 15 | W27: 1984467.3 | Y27: 15 | Z27: 24805.842 | AB27: 15 | AC27: 1959661.5 | AE27: 15 | AF27: 23515938 | AH27: 15 | AI27: 23515938 | AJ27: 297670.1 | AK27: 5878984.4 | AL27: 17636953
A28: 16 | B28: 1373841 | E28: 16 | F28: 343460.25 | I28: 16 | J28: 137384.1 | M28: 16 | N28: 171730.12 | P28: 16 | Q28: 78308.937 | S28: 16 | T28: 43962.912 | V28: 16 | W28: 2148687.3 | Y28: 16 | Z28: 26858.592 | AB28: 16 | AC28: 2121828.7 | AE28: 16 | AF28: 25461945 | AH28: 16 | AI28: 25461945 | AJ28: 322303.1 | AK28: 6365486.2 | AL28: 19096459
A29: 17 | B29: 1056315 | E29: 17 | F29: 264078.75 | I29: 17 | J29: 105631.5 | M29: 17 | N29: 132039.38 | P29: 17 | Q29: 60209.955 | S29: 17 | T29: 33802.08 | V29: 17 | W29: 1652076.7 | Y29: 17 | Z29: 20650.958 | AB29: 17 | AC29: 1631425.7 | AE29: 17 | AF29: 19577108 | AH29: 17 | AI29: 19577108 | AJ29: 247811.5 | AK29: 4894277.1 | AL29: 14682831
A30: Grand Total | B30: 12842379 | E30: Grand Total | F30: 3210594.8 | I30: Grand Total | J30: 1284237.9 | M30: Grand Total | N30: 1605297.4 | P30: Grand Total | Q30: 732015.6 | S30: Grand Total | T30: 410956.13 | V30: Grand Total | W30: 20085481 | Y30: Grand Total | Z30: 251068.51 | AB30: Grand Total | AC30: 19834412 | AE30: Grand Total | AF30: 2.3801295e+08 | AH30: Grand Total | AI30: 2.3801295e+08 | AJ30: 3012822.1 | AK30: 49417916 | AL30: 1.8859503e+08
A33: DEPARTMENT | B33: TOTAL BASIC SALARY | C33: Sum of HOUSING (25%) | D33: Sum of MEDICAL (10%) | E33: Sum of TRANSPORT(12.5%) | F33: Sum of WELFARE (5.7%) | G33: Sum of BONUS (3.2%) | H33: Sum of GROSS EARN | I33: Sum of TAX PER MON (1.25%) | J33: Sum of NET EARN | K33: Sum of ANNUAL NET | L33: Sum of ANNUAL TAX | M33: Sum of ACTUAL NET | N33: Sum of ACTUAL TAX
A34: ACCOUNTING | B34: 4283604 | C34: 1070901 | D34: 428360.4 | E34: 535450.5 | F34: 244165.43 | G34: 137075.33 | H34: 6699556.7 | I34: 83744.458 | J34: 6615812.2 | K34: 79389746 | L34: 1004933.5 | M34: 63047161 | N34: 16342585
A35: ENGINEERING | B35: 2410389 | C35: 602597.25 | D35: 241038.9 | E35: 301298.62 | F35: 137392.17 | G35: 77132.448 | H35: 3769848.4 | I35: 47123.105 | J35: 3722725.3 | K35: 44672703 | L35: 565477.26 | M35: 36782530 | N35: 7890173.4
A36: IT | B36: 1496741 | C36: 374185.25 | D36: 149674.1 | E36: 187092.62 | F36: 85314.237 | G36: 47895.712 | H36: 2340902.9 | I36: 29261.287 | J36: 2311641.6 | K36: 27739700 | L36: 351135.44 | M36: 21143751 | N36: 6595949
A37: SALES | B37: 4651645 | C37: 1162911.2 | D37: 465164.5 | E37: 581455.62 | F37: 265143.76 | G37: 148852.64 | H37: 7275172.8 | I37: 90939.66 | J37: 7184233.1 | K37: 86210797 | L37: 1091275.9 | M37: 67621589 | N37: 18589209
A38: Grand Total | B38: 12842379 | C38: 3210594.8 | D38: 1284237.9 | E38: 1605297.4 | F38: 732015.6 | G38: 410956.13 | H38: 20085481 | I38: 251068.51 | J38: 19834412 | K38: 2.3801295e+08 | L38: 3012822.1 | M38: 1.8859503e+08 | N38: 49417916
B42: Row Labels | C42: Average of BASIC SALARY | D42: Average of HOUSING (25%) | E42: Average of MEDICAL (10%) | F42: Average of TRANSPORT(12.5%) | G42: Average of WELFARE (5.7%) | H42: Average of BONUS (3.2%) | I42: Average of GROSS EARN | J42: Average of TAX PER MON (1.25%) | K42: Average of NET EARN | L42: Average of ANNUAL NET | M42: Average of ANNUAL TAX | N42: Average of ACTUAL TAX | O42: Average of ACTUAL NET
B43: CLERK | C43: 82272.727 | D43: 20568.182 | E43: 8227.2727 | F43: 10284.091 | G43: 4689.5455 | H43: 2632.7273 | I43: 128674.55 | J43: 1608.4318 | K43: 127066.11 | L43: 1524793.4 | M43: 19301.182 | N43: 228719 | O43: 1296074.4
B44: JUNIOR | C44: 127445.45 | D44: 31861.364 | E44: 12744.545 | F44: 15930.682 | G44: 7264.3909 | H44: 4078.2545 | I44: 199324.69 | J44: 2491.5586 | K44: 196833.13 | L44: 2361997.6 | M44: 29898.704 | N44: 437362.97 | O44: 1924634.6
B45: SENIOR | C45: 179444.82 | D45: 44861.205 | E45: 17944.482 | F45: 22430.602 | G45: 10228.355 | H45: 5742.2342 | I45: 280651.7 | J45: 3508.1462 | K45: 277143.55 | L45: 3325722.6 | M45: 42097.754 | N45: 831430.65 | O45: 2494291.9
B46: Grand Total | C46: 129721 | D46: 32430.25 | E46: 12972.1 | F46: 16215.125 | G46: 7394.097 | H46: 4151.072 | I46: 202883.64 | J46: 2536.0455 | K46: 200347.6 | L46: 2404171.2 | M46: 30432.547 | N46: 499170.87 | O46: 1905000.3
A48: Row Labels | B48: Count of BASIC SALARY | C48: Count of HOUSING (25%) | D48: Count of MEDICAL (10%) | E48: Count of TRANSPORT(12.5%) | F48: Count of ACTUAL NET | G48: Count of ACTUAL TAX | H48: Count of ANNUAL TAX | I48: Count of ANNUAL NET | J48: Count of NET EARN | K48: Count of TAX PER MON (1.25%) | L48: Count of GROSS EARN | M48: Count of BONUS (3.2%) | N48: Count of WELFARE (5.7%)
A49: CLERK | B49: 33 | C49: 33 | D49: 33 | E49: 33 | F49: 33 | G49: 33 | H49: 33 | I49: 33 | J49: 33 | K49: 33 | L49: 33 | M49: 33 | N49: 33
A50: JUNIOR | B50: 33 | C50: 33 | D50: 33 | E50: 33 | F50: 33 | G50: 33 | H50: 33 | I50: 33 | J50: 33 | K50: 33 | L50: 33 | M50: 33 | N50: 33
A51: SENIOR | B51: 33 | C51: 33 | D51: 33 | E51: 33 | F51: 33 | G51: 33 | H51: 33 | I51: 33 | J51: 33 | K51: 33 | L51: 33 | M51: 33 | N51: 33
A52: Grand Total | B52: 99 | C52: 99 | D52: 99 | E52: 99 | F52: 99 | G52: 99 | H52: 99 | I52: 99 | J52: 99 | K52: 99 | L52: 99 | M52: 99 | N52: 99
...

Sheet Dash board

Sheet kpi
A2: ='piovt table'!D57 -> TOTAL EMPLOYEE
A3: =GETPIVOTDATA("EMPLOYEE ID",'piovt table'!$C$57) -> 99
A5: TOTAL BASIC SALARY
A6: =GETPIVOTDATA("BASIC SALARY",'piovt table'!$A$3) -> 12842379
A9: TOTAL BASIC SALARY BY SATUS
A10: ='piovt table'!A3 -> STATUS | B10: ='piovt table'!B3 -> TOTAL BASIC SALARY
A11: ='piovt table'!A4 -> CLERK | B11: =GETPIVOTDATA("BASIC SALARY",'piovt table'!$A$3,"STATUS","CLERK") -> 2715000
A12: ='piovt table'!A5 -> JUNIOR | B12: =GETPIVOTDATA("BASIC SALARY",'piovt table'!$A$3,"STATUS","JUNIOR") -> 4205700
A13: ='piovt table'!A6 -> SENIOR | B13: =GETPIVOTDATA("BASIC SALARY",'piovt table'!$A$3,"STATUS","SENIOR") -> 5921679
A14: ='piovt table'!A7 -> Grand Total | B14: =GETPIVOTDATA("BASIC SALARY",'piovt table'!$A$3) -> 12842379
A17: TOTAL BASIC SALARY BY LEVEL
A18: ='piovt table'!A12 -> LEVEL | B18: ='piovt table'!B12 -> TOTAL BASIC SALARY
A19: ='piovt table'!A13 -> 1 | B19: =GETPIVOTDATA("BASIC SALARY",'piovt table'!$A$12,"LEVEL",1) -> 350000
A20: ='piovt table'!A14 -> 2 | B20: =GETPIVOTDATA("BASIC SALARY",'piovt table'!$A$12,"LEVEL",2) -> 450000
A21: ='piovt table'!A15 -> 3 | B21: =GETPIVOTDATA("BASIC SALARY",'piovt table'!$A$12,"LEVEL",3) -> 480000
A22: ='piovt table'!A16 -> 4 | B22: =GETPIVOTDATA("BASIC SALARY",'piovt table'!$A$12,"LEVEL",4) -> 510000
A23: ='piovt table'!A17 -> 5 | B23: =GETPIVOTDATA("BASIC SALARY",'piovt table'!$A$12,"LEVEL",5) -> 450000
A24: ='piovt table'!A18 -> 6 | B24: =GETPIVOTDATA("BASIC SALARY",'piovt table'!$A$12,"LEVEL",6) -> 475000
A29: ='piovt table'!A19 -> 7 | B29: =GETPIVOTDATA("BASIC SALARY",'piovt table'!$A$12,"LEVEL",7) -> 514500
A30: ='piovt table'!A20 -> 8 | B30: =GETPIVOTDATA("BASIC SALARY",'piovt table'!$A$12,"LEVEL",8) -> 677400
A31: ='piovt table'!A21 -> 9 | B31: =GETPIVOTDATA("BASIC SALARY",'piovt table'!$A$12,"LEVEL",9) -> 737400
A32: ='piovt table'!A22 -> 10 | B32: =GETPIVOTDATA("BASIC SALARY",'piovt table'!$A$12,"LEVEL",10) -> 797400
A33: ='piovt table'!A23 -> 11 | B33: =GETPIVOTDATA("BASIC SALARY",'piovt table'!$A$12,"LEVEL",11) -> 714500
A34: ='piovt table'!A24 -> 12 | B34: =GETPIVOTDATA("BASIC SALARY",'piovt table'!$A$12,"LEVEL",12) -> 764500
A35: ='piovt table'!A25 -> 13 | B35: =GETPIVOTDATA("BASIC SALARY",'piovt table'!$A$12,"LEVEL",13) -> 1058841
A36: ='piovt table'!A26 -> 14 | B36: =GETPIVOTDATA("BASIC SALARY",'piovt table'!$A$12,"LEVEL",14) -> 1163841
A37: ='piovt table'!A27 -> 15 | B37: =GETPIVOTDATA("BASIC SALARY",'piovt table'!$A$12,"LEVEL",15) -> 1268841
A38: ='piovt table'!A28 -> 16 | B38: =GETPIVOTDATA("BASIC SALARY",'piovt table'!$A$12,"LEVEL",16) -> 1373841
A39: ='piovt table'!A29 -> 17 | B39: =GETPIVOTDATA("BASIC SALARY",'piovt table'!$A$12,"LEVEL",17) -> 1056315
A40: ='piovt table'!A30 -> Grand Total | B40: =GETPIVOTDATA("BASIC SALARY",'piovt table'!$A$12) -> 12842379
A42: TOTAL BASIC SALARY BY DEPARTMENT
A43: ='piovt table'!A33 -> DEPARTMENT | B43: ='piovt table'!B33 -> TOTAL BASIC SALARY
A44: ='piovt table'!A34 -> ACCOUNTING | B44: =GETPIVOTDATA("TOTAL BASIC SALARY",'piovt table'!$A$33,"DEPARTMENT","ACCOUNTING") -> 4283604
A45: ='piovt table'!A35 -> ENGINEERING | B45: =GETPIVOTDATA("TOTAL BASIC SALARY",'piovt table'!$A$33,"DEPARTMENT","ENGINEERING") -> 2410389
A46: ='piovt table'!A36 -> IT | B46: =GETPIVOTDATA("TOTAL BASIC SALARY",'piovt table'!$A$33,"DEPARTMENT","IT") -> 1496741
A47: ='piovt table'!A37 -> SALES | B47: =GETPIVOTDATA("TOTAL BASIC SALARY",'piovt table'!$A$33,"DEPARTMENT","SALES") -> 4651645
A48: ='piovt table'!A38 -> Grand Total | B48: =GETPIVOTDATA("TOTAL BASIC SALARY",'piovt table'!$A$33) -> 12842379

Sheet Sheet1
A1: S/N | B1: EMPLOYEE ID | C1: NAME | D1: LEVEL | E1: STATUS | F1: DEPARTMENT | G1: BASIC SALARY | H1: HOUSING (25%) | I1: MEDICAL (10%) | J1: TRANSPORT(12.5%) | K1: WELFARE (5.7%) | L1: BONUS (3.2%) | M1: GROSS EARN | N1: TAX PER MON (1.25%) | O1: NET EARN | P1: ANNUAL NET | Q1: ANNUAL TAX | R1: ACTUAL TAX | S1: ACTUAL NET
A2: 1 | B2: 10001 | C2: Bashir Halimah | D2: 1 | E2: CLERK | F2: ACCOUNTING | G2: 70000 | H2: =IF(E2="SENIOR",G2*25%,IF(E2="JUNIOR",G2*25%,IF(E2="CLERK",G2*25%,"Value Not Match"))) -> 17500 | I2: =IF(E2="SENIOR",G2*10%,IF(E2="JUNIOR",G2*10%,IF(E2="CLERK",G2*10%,"Value Not Match"))) -> 7000 | J2: =IF(E2="SENIOR",G2*12.5%,IF(E2="JUNIOR",G2*12.5%,IF(E2="CLERK",G2*12.5%,"Value Not Match"))) -> 8750 | K2: =IF(E2="SENIOR",G2*5.7%,IF(E2="JUNIOR",G2*5.7%,IF(E2="CLERK",G2*5.7%,"Value Not Match"))) -> 3990 | L2: =IF(E2="SENIOR",G2*3.2%,IF(E2="JUNIOR",G2*3.2%,IF(E2="CLERK",G2*3.2%,"Value Not Match"))) -> 2240 | M2: =SUM(G2:L2) -> 109480 | N2: =M2*1.25% -> 1368.5 | O2: =M2-N2 -> 108111.5 | P2: =O2*12 -> 1297338 | Q2: =N2*12 -> 16422 | R2: =IF(P2>=2500000,P2*25%,IF(P2>=801000,P2*15%,IF(P2<=800000,"Exempted"))) -> 194600.7 | S2: =P2-R2 -> 1102737.3
A3: 2 | B3: 10002 | C3: Ola Titi | D3: 7 | E3: JUNIOR | F3: SALES | G3: 102900 | H3: =IF(E3="SENIOR",G3*25%,IF(E3="JUNIOR",G3*25%,IF(E3="CLERK",G3*25%,"Value Not Match"))) -> 25725 | I3: =IF(E3="SENIOR",G3*10%,IF(E3="JUNIOR",G3*10%,IF(E3="CLERK",G3*10%,"Value Not Match"))) -> 10290 | J3: =IF(E3="SENIOR",G3*12.5%,IF(E3="JUNIOR",G3*12.5%,IF(E3="CLERK",G3*12.5%,"Value Not Match"))) -> 12862.5 | K3: =IF(E3="SENIOR",G3*5.7%,IF(E3="JUNIOR",G3*5.7%,IF(E3="CLERK",G3*5.7%,"Value Not Match"))) -> 5865.3 | L3: =IF(E3="SENIOR",G3*3.2%,IF(E3="JUNIOR",G3*3.2%,IF(E3="CLERK",G3*3.2%,"Value Not Match"))) -> 3292.8 | M3: =SUM(G3:L3) -> 160935.6 | N3: =M3*1.25% -> 2011.695 | O3: =M3-N3 -> 158923.9 | P3: =O3*12 -> 1907086.9 | Q3: =N3*12 -> 24140.34 | R3: =IF(P3>=2500000,P3*25%,IF(P3>=801000,P3*15%,IF(P3<=800000,"Exempted"))) -> 286063.03 | S3: =P3-R3 -> 1621023.8
A4: 3 | B4: 10003 | C4: Bello Musa | D4: 13 | E4: SENIOR | F4: IT | G4: 151263 | H4: =IF(E4="SENIOR",G4*25%,IF(E4="JUNIOR",G4*25%,IF(E4="CLERK",G4*25%,"Value Not Match"))) -> 37815.75 | I4: =IF(E4="SENIOR",G4*10%,IF(E4="JUNIOR",G4*10%,IF(E4="CLERK",G4*10%,"Value Not Match"))) -> 15126.3 | J4: =IF(E4="SENIOR",G4*12.5%,IF(E4="JUNIOR",G4*12.5%,IF(E4="CLERK",G4*12.5%,"Value Not Match"))) -> 18907.875 | K4: =IF(E4="SENIOR",G4*5.7%,IF(E4="JUNIOR",G4*5.7%,IF(E4="CLERK",G4*5.7%,"Value Not Match"))) -> 8621.991 | L4: =IF(E4="SENIOR",G4*3.2%,IF(E4="JUNIOR",G4*3.2%,IF(E4="CLERK",G4*3.2%,"Value Not Match"))) -> 4840.416 | M4: =SUM(G4:L4) -> 236575.33 | N4: =M4*1.25% -> 2957.1917 | O4: =M4-N4 -> 233618.14 | P4: =O4*12 -> 2803417.7 | Q4: =N4*12 -> 35486.3 | R4: =IF(P4>=2500000,P4*25%,IF(P4>=801000,P4*15%,IF(P4<=800000,"Exempted"))) -> 700854.42 | S4: =P4-R4 -> 2102563.3
A5: 4 | B5: 10004 | C5: Okafor Chidi | D5: 2 | E5: CLERK | F5: ENGINEERING | G5: 75000 | H5: =IF(E5="SENIOR",G5*25%,IF(E5="JUNIOR",G5*25%,IF(E5="CLERK",G5*25%,"Value Not Match"))) -> 18750 | I5: =IF(E5="SENIOR",G5*10%,IF(E5="JUNIOR",G5*10%,IF(E5="CLERK",G5*10%,"Value Not Match"))) -> 7500 | J5: =IF(E5="SENIOR",G5*12.5%,IF(E5="JUNIOR",G5*12.5%,IF(E5="CLERK",G5*12.5%,"Value Not Match"))) -> 9375 | K5: =IF(E5="SENIOR",G5*5.7%,IF(E5="JUNIOR",G5*5.7%,IF(E5="CLERK",G5*5.7%,"Value Not Match"))) -> 4275 | L5: =IF(E5="SENIOR",G5*3.2%,IF(E5="JUNIOR",G5*3.2%,IF(E5="CLERK",G5*3.2%,"Value Not Match"))) -> 2400 | M5: =SUM(G5:L5) -> 117300 | N5: =M5*1.25% -> 1466.25 | O5: =M5-N5 -> 115833.75 | P5: =O5*12 -> 1390005 | Q5: =N5*12 -> 17595 | R5: =IF(P5>=2500000,P5*25%,IF(P5>=801000,P5*15%,IF(P5<=800000,"Exempted"))) -> 208500.75 | S5: =P5-R5 -> 1181504.2
A6: 5 | B6: 10005 | C6: Yusuf Zara | D6: 8 | E6: JUNIOR | F6: ACCOUNTING | G6: 112900 | H6: =IF(E6="SENIOR",G6*25%,IF(E6="JUNIOR",G6*25%,IF(E6="CLERK",G6*25%,"Value Not Match"))) -> 28225 | I6: =IF(E6="SENIOR",G6*10%,IF(E6="JUNIOR",G6*10%,IF(E6="CLERK",G6*10%,"Value Not Match"))) -> 11290 | J6: =IF(E6="SENIOR",G6*12.5%,IF(E6="JUNIOR",G6*12.5%,IF(E6="CLERK",G6*12.5%,"Value Not Match"))) -> 14112.5 | K6: =IF(E6="SENIOR",G6*5.7%,IF(E6="JUNIOR",G6*5.7%,IF(E6="CLERK",G6*5.7%,"Value Not Match"))) -> 6435.3 | L6: =IF(E6="SENIOR",G6*3.2%,IF(E6="JUNIOR",G6*3.2%,IF(E6="CLERK",G6*3.2%,"Value Not Match"))) -> 3612.8 | M6: =SUM(G6:L6) -> 176575.6 | N6: =M6*1.25% -> 2207.195 | O6: =M6-N6 -> 174368.4 | P6: =O6*12 -> 2092420.9 | Q6: =N6*12 -> 26486.34 | R6: =IF(P6>=2500000,P6*25%,IF(P6>=801000,P6*15%,IF(P6<=800000,"Exempted"))) -> 313863.13 | S6: =P6-R6 -> 1778557.7
A7: 6 | B7: 10006 | C7: Adewale Bola | D7: 14 | E7: SENIOR | F7: SALES | G7: 166263 | H7: =IF(E7="SENIOR",G7*25%,IF(E7="JUNIOR",G7*25%,IF(E7="CLERK",G7*25%,"Value Not Match"))) -> 41565.75 | I7: =IF(E7="SENIOR",G7*10%,IF(E7="JUNIOR",G7*10%,IF(E7="CLERK",G7*10%,"Value Not Match"))) -> 16626.3 | J7: =IF(E7="SENIOR",G7*12.5%,IF(E7="JUNIOR",G7*12.5%,IF(E7="CLERK",G7*12.5%,"Value Not Match"))) -> 20782.875 | K7: =IF(E7="SENIOR",G7*5.7%,IF(E7="JUNIOR",G7*5.7%,IF(E7="CLERK",G7*5.7%,"Value Not Match"))) -> 9476.991 | L7: =IF(E7="SENIOR",G7*3.2%,IF(E7="JUNIOR",G7*3.2%,IF(E7="CLERK",G7*3.2%,"Value Not Match"))) -> 5320.416 | M7: =SUM(G7:L7) -> 260035.33 | N7: =M7*1.25% -> 3250.4417 | O7: =M7-N7 -> 256784.89 | P7: =O7*12 -> 3081418.7 | Q7: =N7*12 -> 39005.3 | R7: =IF(P7>=2500000,P7*25%,IF(P7>=801000,P7*15%,IF(P7<=800000,"Exempted"))) -> 770354.67 | S7: =P7-R7 -> 2311064
A8: 7 | B8: 10007 | C8: Etim Grace | D8: 3 | E8: CLERK | F8: ENGINEERING | G8: 80000 | H8: =IF(E8="SENIOR",G8*25%,IF(E8="JUNIOR",G8*25%,IF(E8="CLERK",G8*25%,"Value Not Match"))) -> 20000 | I8: =IF(E8="SENIOR",G8*10%,IF(E8="JUNIOR",G8*10%,IF(E8="CLERK",G8*10%,"Value Not Match"))) -> 8000 | J8: =IF(E8="SENIOR",G8*12.5%,IF(E8="JUNIOR",G8*12.5%,IF(E8="CLERK",G8*12.5%,"Value Not Match"))) -> 10000 | K8: =IF(E8="SENIOR",G8*5.7%,IF(E8="JUNIOR",G8*5.7%,IF(E8="CLERK",G8*5.7%,"Value Not Match"))) -> 4560 | L8: =IF(E8="SENIOR",G8*3.2%,IF(E8="JUNIOR",G8*3.2%,IF(E8="CLERK",G8*3.2%,"Value Not Match"))) -> 2560 | M8: =SUM(G8:L8) -> 125120 | N8: =M8*1.25% -> 1564 | O8: =M8-N8 -> 123556 | P8: =O8*12 -> 1482672 | Q8: =N8*12 -> 18768 | R8: =IF(P8>=2500000,P8*25%,IF(P8>=801000,P8*15%,IF(P8<=800000,"Exempted"))) -> 222400.8 | S8: =P8-R8 -> 1260271.2
A9: 8 | B9: 10008 | C9: Nwosu Kelvin | D9: 9 | E9: JUNIOR | F9: ACCOUNTING | G9: 122900 | H9: =IF(E9="SENIOR",G9*25%,IF(E9="JUNIOR",G9*25%,IF(E9="CLERK",G9*25%,"Value Not Match"))) -> 30725 | I9: =IF(E9="SENIOR",G9*10%,IF(E9="JUNIOR",G9*10%,IF(E9="CLERK",G9*10%,"Value Not Match"))) -> 12290 | J9: =IF(E9="SENIOR",G9*12.5%,IF(E9="JUNIOR",G9*12.5%,IF(E9="CLERK",G9*12.5%,"Value Not Match"))) -> 15362.5 | K9: =IF(E9="SENIOR",G9*5.7%,IF(E9="JUNIOR",G9*5.7%,IF(E9="CLERK",G9*5.7%,"Value Not Match"))) -> 7005.3 | L9: =IF(E9="SENIOR",G9*3.2%,IF(E9="JUNIOR",G9*3.2%,IF(E9="CLERK",G9*3.2%,"Value Not Match"))) -> 3932.8 | M9: =SUM(G9:L9) -> 192215.6 | N9: =M9*1.25% -> 2402.695 | O9: =M9-N9 -> 189812.9 | P9: =O9*12 -> 2277754.9 | Q9: =N9*12 -> 28832.34 | R9: =IF(P9>=2500000,P9*25%,IF(P9>=801000,P9*15%,IF(P9<=800000,"Exempted"))) -> 341663.23 | S9: =P9-R9 -> 1936091.6
A10: 9 | B10: 10009 | C10: Garba Amina | D10: 15 | E10: SENIOR | F10: SALES | G10: 181263 | H10: =IF(E10="SENIOR",G10*25%,IF(E10="JUNIOR",G10*25%,IF(E10="CLERK",G10*25%,"Value Not Match"))) -> 45315.75 | I10: =IF(E10="SENIOR",G10*10%,IF(E10="JUNIOR",G10*10%,IF(E10="CLERK",G10*10%,"Value Not Match"))) -> 18126.3 | J10: =IF(E10="SENIOR",G10*12.5%,IF(E10="JUNIOR",G10*12.5%,IF(E10="CLERK",G10*12.5%,"Value Not Match"))) -> 22657.875 | K10: =IF(E10="SENIOR",G10*5.7%,IF(E10="JUNIOR",G10*5.7%,IF(E10="CLERK",G10*5.7%,"Value Not Match"))) -> 10331.991 | L10: =IF(E10="SENIOR",G10*3.2%,IF(E10="JUNIOR",G10*3.2%,IF(E10="CLERK",G10*3.2%,"Value Not Match"))) -> 5800.416 | M10: =SUM(G10:L10) -> 283495.33 | N10: =M10*1.25% -> 3543.6917 | O10: =M10-N10 -> 279951.64 | P10: =O10*12 -> 3359419.7 | Q10: =N10*12 -> 42524.3 | R10: =IF(P10>=2500000,P10*25%,IF(P10>=801000,P10*15%,IF(P10<=800000,"Exempted"))) -> 839854.92 | S10: =P10-R10 -> 2519564.8
A11: 10 | B11: 10010 | C11: Okon Peace | D11: 4 | E11: CLERK | F11: ENGINEERING | G11: 85000 | H11: =IF(E11="SENIOR",G11*25%,IF(E11="JUNIOR",G11*25%,IF(E11="CLERK",G11*25%,"Value Not Match"))) -> 21250 | I11: =IF(E11="SENIOR",G11*10%,IF(E11="JUNIOR",G11*10%,IF(E11="CLERK",G11*10%,"Value Not Match"))) -> 8500 | J11: =IF(E11="SENIOR",G11*12.5%,IF(E11="JUNIOR",G11*12.5%,IF(E11="CLERK",G11*12.5%,"Value Not Match"))) -> 10625 | K11: =IF(E11="SENIOR",G11*5.7%,IF(E11="JUNIOR",G11*5.7%,IF(E11="CLERK",G11*5.7%,"Value Not Match"))) -> 4845 | L11: =IF(E11="SENIOR",G11*3.2%,IF(E11="JUNIOR",G11*3.2%,IF(E11="CLERK",G11*3.2%,"Value Not Match"))) -> 2720 | M11: =SUM(G11:L11) -> 132940 | N11: =M11*1.25% -> 1661.75 | O11: =M11-N11 -> 131278.25 | P11: =O11*12 -> 1575339 | Q11: =N11*12 -> 19941 | R11: =IF(P11>=2500000,P11*25%,IF(P11>=801000,P11*15%,IF(P11<=800000,"Exempted"))) -> 236300.85 | S11: =P11-R11 -> 1339038.1
A12: 11 | B12: 10011 | C12: Chukwu Ify | D12: 10 | E12: JUNIOR | F12: SALES | G12: 132900 | H12: =IF(E12="SENIOR",G12*25%,IF(E12="JUNIOR",G12*25%,IF(E12="CLERK",G12*25%,"Value Not Match"))) -> 33225 | I12: =IF(E12="SENIOR",G12*10%,IF(E12="JUNIOR",G12*10%,IF(E12="CLERK",G12*10%,"Value Not Match"))) -> 13290 | J12: =IF(E12="SENIOR",G12*12.5%,IF(E12="JUNIOR",G12*12.5%,IF(E12="CLERK",G12*12.5%,"Value Not Match"))) -> 16612.5 | K12: =IF(E12="SENIOR",G12*5.7%,IF(E12="JUNIOR",G12*5.7%,IF(E12="CLERK",G12*5.7%,"Value Not Match"))) -> 7575.3 | L12: =IF(E12="SENIOR",G12*3.2%,IF(E12="JUNIOR",G12*3.2%,IF(E12="CLERK",G12*3.2%,"Value Not Match"))) -> 4252.8 | M12: =SUM(G12:L12) -> 207855.6 | N12: =M12*1.25% -> 2598.195 | O12: =M12-N12 -> 205257.4 | P12: =O12*12 -> 2463088.9 | Q12: =N12*12 -> 31178.34 | R12: =IF(P12>=2500000,P12*25%,IF(P12>=801000,P12*15%,IF(P12<=800000,"Exempted"))) -> 369463.33 | S12: =P12-R12 -> 2093625.5
A13: 12 | B13: 10012 | C13: Salami Kunle | D13: 16 | E13: SENIOR | F13: ACCOUNTING | G13: 196263 | H13: =IF(E13="SENIOR",G13*25%,IF(E13="JUNIOR",G13*25%,IF(E13="CLERK",G13*25%,"Value Not Match"))) -> 49065.75 | I13: =IF(E13="SENIOR",G13*10%,IF(E13="JUNIOR",G13*10%,IF(E13="CLERK",G13*10%,"Value Not Match"))) -> 19626.3 | J13: =IF(E13="SENIOR",G13*12.5%,IF(E13="JUNIOR",G13*12.5%,IF(E13="CLERK",G13*12.5%,"Value Not Match"))) -> 24532.875 | K13: =IF(E13="SENIOR",G13*5.7%,IF(E13="JUNIOR",G13*5.7%,IF(E13="CLERK",G13*5.7%,"Value Not Match"))) -> 11186.991 | L13: =IF(E13="SENIOR",G13*3.2%,IF(E13="JUNIOR",G13*3.2%,IF(E13="CLERK",G13*3.2%,"Value Not Match"))) -> 6280.416 | M13: =SUM(G13:L13) -> 306955.33 | N13: =M13*1.25% -> 3836.9417 | O13: =M13-N13 -> 303118.39 | P13: =O13*12 -> 3637420.7 | Q13: =N13*12 -> 46043.3 | R13: =IF(P13>=2500000,P13*25%,IF(P13>=801000,P13*15%,IF(P13<=800000,"Exempted"))) -> 909355.17 | S13: =P13-R13 -> 2728065.5
... A100: 99 | B100: 10099 | C100: Adebayo Adebola | D100: 14 | E100: SENIOR | F100: IT | G100: 166263 | H100: =IF(E100="SENIOR",G100*25%,IF(E100="JUNIOR",G100*25%,IF(E100="CLERK",G100*25%,"Value Not Match"))) -> 41565.75 | I100: =IF(E100="SENIOR",G100*10%,IF(E100="JUNIOR",G100*10%,IF(E100="CLERK",G100*10%,"Value Not Match"))) -> 16626.3 | J100: =IF(E100="SENIOR",G100*12.5%,IF(E100="JUNIOR",G100*12.5%,IF(E100="CLERK",G100*12.5%,"Value Not Match"))) -> 20782.875 | K100: =IF(E100="SENIOR",G100*5.7%,IF(E100="JUNIOR",G100*5.7%,IF(E100="CLERK",G100*5.7%,"Value Not Match"))) -> 9476.991 | L100: =IF(E100="SENIOR",G100*3.2%,IF(E100="JUNIOR",G100*3.2%,IF(E100="CLERK",G100*3.2%,"Value Not Match"))) -> 5320.416 | M100: =SUM(G100:L100) -> 260035.33 | N100: =M100*1.25% -> 3250.4417 | O100: =M100-N100 -> 256784.89 | P100: =O100*12 -> 3081418.7 | Q100: =N100*12 -> 39005.3 | R100: =IF(P100>=2500000,P100*25%,IF(P100>=801000,P100*15%,IF(P100<=800000,"Exempted"))) -> 770354.67 | S100: =P100-R100 -> 2311064
F102: HIGHEST VALUE | G102: =MAX(G2:G100) -> 211263 | H102: =MAX(H2:H100) -> 52815.75 | I102: =MAX(I2:I100) -> 21126.3 | J102: =MAX(J2:J100) -> 26407.875 | K102: =MAX(K2:K100) -> 12041.991 | L102: =MAX(L2:L100) -> 6760.416 | M102: =MAX(M2:M100) -> 330415.33 | N102: =MAX(N2:N100) -> 4130.1916 | ... S102: =MAX(S2:S100) -> 2936566.3
F103: LOWEST VALUE | G103: =MIN(G2:G100) -> 70000 | H103: =MIN(H2:H100) -> 17500 | I103: =MIN(I2:I100) -> 7000 | J103: =MIN(J2:J100) -> 8750 | K103: =MIN(K2:K100) -> 3990 | L103: =MIN(L2:L100) -> 2240 | M103: =MIN(M2:M100) -> 109480 | N103: =MIN(N2:N100) -> 1368.5 | ... S103: =MIN(S2:S100) -> 1102737.3
F111: LEVEL | G111: TOTAL BS | H111: TOTAL HOUSING | I111: TOTAL MEDICAL | J111: TOTAL TRANSPORT
F112: 1 | G112: =SUMIF(D2:D100,"1",G2:G100) -> 350000 | H112: =SUMIF(D2:D100,"1",H2:H100) -> 87500 | I112: =SUMIF(D2:D100,"1",I2:I100) -> 35000 | J112: =SUMIF(D2:D100,"1",J2:J100) -> 43750
F113: 2 | G113: =SUMIF(D2:D100,"2",G2:G100) -> 450000 | H113: =SUMIF(D2:D100,"2",H2:H100) -> 112500 | I113: =SUMIF(D2:D100,"2",I2:I100) -> 45000 | J113: =SUMIF(D2:D100,"2",J2:J100) -> 56250
F114: 3 | G114: =SUMIF(D2:D100,"3",G2:G100) -> 480000 | H114: =SUMIF(D2:D100,"3",H2:H100) -> 120000 | I114: =SUMIF(D2:D100,"3",I2:I100) -> 48000 | J114: =SUMIF(D2:D100,"3",J2:J100) -> 60000
F115: 4 | G115: =SUMIF(D2:D100,"4",G2:G100) -> 510000 | H115: =SUMIF(D2:D100,"4",H2:H100) -> 127500 | I115: =SUMIF(D2:D100,"4",I2:I100) -> 51000 | J115: =SUMIF(D2:D100,"4",J2:J100) -> 63750
F116: 5 | G116: =SUMIF(D2:D100,"5",G2:G100) -> 450000 | H116: =SUMIF(D2:D100,"5",H2:H100) -> 112500 | I116: =SUMIF(D2:D100,"5",I2:I100) -> 45000 | J116: =SUMIF(D2:D100,"5",J2:J100) -> 56250
F117: 6 | G117: =SUMIF(D2:D100,"6",G2:G100) -> 475000 | H117: =SUMIF(D2:D100,"6",H2:H100) -> 118750 | I117: =SUMIF(D2:D100,"6",I2:I100) -> 47500 | J117: =SUMIF(D2:D100,"6",J2:J100) -> 59375
F118: 7 | G118: =SUMIF(D2:D100,"7",G2:G100) -> 514500 | H118: =SUMIF(D2:D100,"7",H2:H100) -> 128625 | I118: =SUMIF(D2:D100,"7",I2:I100) -> 51450 | J118: =SUMIF(D2:D100,"7",J2:J100) -> 64312.5
F119: 8 | G119: =SUMIF(D2:D100,"8",G2:G100) -> 677400 | H119: =SUMIF(D2:D100,"8",H2:H100) -> 169350 | I119: =SUMIF(D2:D100,"8",I2:I100) -> 67740 | J119: =SUMIF(D2:D100,"8",J2:J100) -> 84675
F120: 9 | G120: =SUMIF(D2:D100,"9",G2:G100) -> 737400 | H120: =SUMIF(D2:D100,"9",H2:H100) -> 184350 | I120: =SUMIF(D2:D100,"9",I2:I100) -> 73740 | J120: =SUMIF(D2:D100,"9",J2:J100) -> 92175
F121: 10 | G121: =SUMIF(D2:D100,"10",G2:G100) -> 797400 | H121: =SUMIF(D2:D100,"10",H2:H100) -> 199350 | I121: =SUMIF(D2:D100,"10",I2:I100) -> 79740 | J121: =SUMIF(D2:D100,"10",J2:J100) -> 99675
F122: 11 | G122: =SUMIF(D2:D100,"11",G2:G100) -> 714500 | H122: =SUMIF(D2:D100,"11",H2:H100) -> 178625 | I122: =SUMIF(D2:D100,"11",I2:I100) -> 71450 | J122: =SUMIF(D2:D100,"11",J2:J100) -> 89312.5
F123: 12 | G123: =SUMIF(D2:D100,"12",G2:G100) -> 764500 | H123: =SUMIF(D2:D100,"12",H2:H100) -> 191125 | I123: =SUMIF(D2:D100,"12",I2:I100) -> 76450 | J123: =SUMIF(D2:D100,"12",J2:J100) -> 95562.5
F124: 13 | G124: =SUMIF(D2:D100,"13",G2:G100) -> 1058841 | H124: =SUMIF(D2:D100,"13",H2:H100) -> 264710.25 | I124: =SUMIF(D2:D100,"13",I2:I100) -> 105884.1 | J124: =SUMIF(D2:D100,"13",J2:J100) -> 132355.12
F125: 14 | G125: =SUMIF(D2:D100,"14",G2:G100) -> 1163841 | H125: =SUMIF(D2:D100,"14",H2:H100) -> 290960.25 | I125: =SUMIF(D2:D100,"14",I2:I100) -> 116384.1 | J125: =SUMIF(D2:D100,"14",J2:J100) -> 145480.12
F126: 15 | G126: =SUMIF(D2:D100,"15",G2:G100) -> 1268841 | H126: =SUMIF(D2:D100,"15",H2:H100) -> 317210.25 | I126: =SUMIF(D2:D100,"15",I2:I100) -> 126884.1 | J126: =SUMIF(D2:D100,"15",J2:J100) -> 158605.12
F127: 16 | G127: =SUMIF(D2:D100,"16",G2:G100) -> 1373841 | H127: =SUMIF(D2:D100,"16",H2:H100) -> 343460.25 | I127: =SUMIF(D2:D100,"16",I2:I100) -> 137384.1 | J127: =SUMIF(D2:D100,"16",J2:J100) -> 171730.12
F128: 17 | G128: =SUMIF(D2:D100,"17",G2:G100) -> 1056315 | H128: =SUMIF(D2:D100,"17",H2:H100) -> 264078.75 | I128: =SUMIF(D2:D100,"17",I2:I100) -> 105631.5 | J128: =SUMIF(D2:D100,"17",J2:J100) -> 132039.38
F129: TOTAL | G129: =SUM(G112:G128) -> 12842379 | H129: =SUM(H112:H128) -> 3210594.8 | I129: =SUM(I112:I128) -> 1284237.9 | J129: =SUM(J112:J128) -> 1605297.4
F131: DEPARTMENT | G131: BAISC SALARY | H131: AVERAGE | I131: DEPARTMENT | J131: NO OF EMPLOYEES
F132: {=_xlfn.UNIQUE(F2:F100)} -> ACCOUNTING | G132: =SUMIF(F2:F100,"ACCOUNTING",G2:G100) -> 4283604 | H132: =AVERAGEIF(F2:F100,"ACCOUNTING",G2:G100) -> 129806.18 | I132: ACCOUNTING | J132: =COUNTIF(F2:F100,"ACCOUNTING") -> 33
F133: SALES | G133: =SUMIF(F2:F100,"SALES",G2:G100) -> 4651645 | H133: =AVERAGEIF(F2:F100,"SALES",G2:G100) -> 140958.94 | I133: SALES | J133: =COUNTIF(F2:F100,"SALES") -> 33
F134: IT | G134: =SUMIF(F2:F100,"IT",G2:G100) -> 1496741 | H134: =AVERAGEIF(F2:F100,"IT",G2:G100) -> 166304.56 | I134: IT | J134: =COUNTIF(F2:F100,"IT") -> 9
F135: ENGINEERING | G135: =SUMIF(F2:F100,"ENGINEERING",G2:G100) -> 2410389 | H135: =AVERAGEIF(F2:F100,"ENGINEERING",G2:G100) -> 100432.88 | I135: ENGINEERING | J135: =COUNTIF(F2:F100,"ENGINEERING") -> 24
...

Sheet SENIOR
A1: 3 | B1: 10003 | C1: Bello Musa | D1: 13 | E1: SENIOR | F1: IT | G1: 151263 | H1: 37815.75 | I1: 15126.3 | J1: 18907.875 | K1: 8621.991 | L1: 4840.416 | M1: 236575.33 | N1: 2957.1917 | O1: 233618.14 | P1: 2803417.7 | Q1: 35486.3 | R1: 700854.42 | S1: 2102563.3
A2: 6 | B2: 10006 | C2: Adewale Bola | D2: 14 | E2: SENIOR | F2: SALES | G2: 166263 | H2: 41565.75 | I2: 16626.3 | J2: 20782.875 | K2: 9476.991 | L2: 5320.416 | M2: 260035.33 | N2: 3250.4417 | O2: 256784.89 | P2: 3081418.7 | Q2: 39005.3 | R2: 770354.67 | S2: 2311064
A3: 9 | B3: 10009 | C3: Garba Amina | D3: 15 | E3: SENIOR | F3: SALES | G3: 181263 | H3: 45315.75 | I3: 18126.3 | J3: 22657.875 | K3: 10331.991 | L3: 5800.416 | M3: 283495.33 | N3: 3543.6917 | O3: 279951.64 | P3: 3359419.7 | Q3: 42524.3 | R3: 839854.92 | S3: 2519564.8
A4: 12 | B4: 10012 | C4: Salami Kunle | D4: 16 | E4: SENIOR | F4: ACCOUNTING | G4: 196263 | H4: 49065.75 | I4: 19626.3 | J4: 24532.875 | K4: 11186.991 | L4: 6280.416 | M4: 306955.33 | N4: 3836.9417 | O4: 303118.39 | P4: 3637420.7 | Q4: 46043.3 | R4: 909355.17 | S4: 2728065.5
A5: 15 | B5: 10015 | C5: Ibrahim Fatima | D5: 17 | E5: SENIOR | F5: IT | G5: 211263 | H5: 52815.75 | I5: 21126.3 | J5: 26407.875 | K5: 12041.991 | L5: 6760.416 | M5: 330415.33 | N5: 4130.1916 | O5: 326285.14 | P5: 3915421.7 | Q5: 49562.3 | R5: 978855.42 | S5: 2936566.3
A6: 18 | B6: 10018 | C6: Nwosu Kelvin | D6: 13 | E6: SENIOR | F6: SALES | G6: 151263 | H6: 37815.75 | I6: 15126.3 | J6: 18907.875 | K6: 8621.991 | L6: 4840.416 | M6: 236575.33 | N6: 2957.1917 | O6: 233618.14 | P6: 2803417.7 | Q6: 35486.3 | R6: 700854.42 | S6: 2102563.3
A7: 21 | B7: 10021 | C7: Adamu Rasak | D7: 14 | E7: SENIOR | F7: SALES | G7: 166263 | H7: 41565.75 | I7: 16626.3 | J7: 20782.875 | K7: 9476.991 | L7: 5320.416 | M7: 260035.33 | N7: 3250.4417 | O7: 256784.89 | P7: 3081418.7 | Q7: 39005.3 | R7: 770354.67 | S7: 2311064
A8: 24 | B8: 10024 | C8: Efflong Comfort | D8: 15 | E8: SENIOR | F8: ACCOUNTING | G8: 181263 | H8: 45315.75 | I8: 18126.3 | J8: 22657.875 | K8: 10331.991 | L8: 5800.416 | M8: 283495.33 | N8: 3543.6917 | O8: 279951.64 | P8: 3359419.7 | Q8: 42524.3 | R8: 839854.92 | S8: 2519564.8
A9: 27 | B9: 10027 | C9: Akande Faidat | D9: 16 | E9: SENIOR | F9: IT | G9: 196263 | H9: 49065.75 | I9: 19626.3 | J9: 24532.875 | K9: 11186.991 | L9: 6280.416 | M9: 306955.33 | N9: 3836.9417 | O9: 303118.39 | P9: 3637420.7 | Q9: 46043.3 | R9: 909355.17 | S9: 2728065.5
A10: 30 | B10: 10030 | C10: Haassan Ola | D10: 17 | E10: SENIOR | F10: SALES | G10: 211263 | H10: 52815.75 | I10: 21126.3 | J10: 26407.875 | K10: 12041.991 | L10: 6760.416 | M10: 330415.33 | N10: 4130.1916 | O10: 326285.14 | P10: 3915421.7 | Q10: 49562.3 | R10: 978855.42 | S10: 2936566.3
A11: 33 | B11: 10033 | C11: Eze Chiwe | D11: 13 | E11: SENIOR | F11: SALES | G11: 151263 | H11: 37815.75 | I11: 15126.3 | J11: 18907.875 | K11: 8621.991 | L11: 4840.416 | M11: 236575.33 | N11: 2957.1917 | O11: 233618.14 | P11: 2803417.7 | Q11: 35486.3 | R11: 700854.42 | S11: 2102563.3
A12: 36 | B12: 10036 | C12: Muhameed Bashir | D12: 14 | E12: SENIOR | F12: ACCOUNTING | G12: 166263 | H12: 41565.75 | I12: 16626.3 | J12: 20782.875 | K12: 9476.991 | L12: 5320.416 | M12: 260035.33 | N12: 3250.4417 | O12: 256784.89 | P12: 3081418.7 | Q12: 39005.3 | R12: 770354.67 | S12: 2311064
... A33: 99 | B33: 10099 | C33: Adebayo Adebola | D33: 14 | E33: SENIOR | F33: IT | G33: 166263 | H33: 41565.75 | I33: 16626.3 | J33: 20782.875 | K33: 9476.991 | L33: 5320.416 | M33: 260035.33 | N33: 3250.4417 | O33: 256784.89 | P33: 3081418.7 | Q33: 39005.3 | R33: 770354.67 | S33: 2311064

Sheet JUNIOR
A1: 2 | B1: 10002 | C1: Ola Titi | D1: 7 | E1: JUNIOR | F1: SALES | G1: 102900 | H1: 25725 | I1: 10290 | J1: 12862.5 | K1: 5865.3 | L1: 3292.8 | M1: 160935.6 | N1: 2011.695 | O1: 158923.9 | P1: 1907086.9 | Q1: 24140.34 | R1: 286063.03 | S1: 1621023.8
A2: 5 | B2: 10005 | C2: Yusuf Zara | D2: 8 | E2: JUNIOR | F2: ACCOUNTING | G2: 112900 | H2: 28225 | I2: 11290 | J2: 14112.5 | K2: 6435.3 | L2: 3612.8 | M2: 176575.6 | N2: 2207.195 | O2: 174368.4 | P2: 2092420.9 | Q2: 26486.34 | R2: 313863.13 | S2: 1778557.7
A3: 8 | B3: 10008 | C3: Nwosu Kelvin | D3: 9 | E3: JUNIOR | F3: ACCOUNTING | G3: 122900 | H3: 30725 | I3: 12290 | J3: 15362.5 | K3: 7005.3 | L3: 3932.8 | M3: 192215.6 | N3: 2402.695 | O3: 189812.9 | P3: 2277754.9 | Q3: 28832.34 | R3: 341663.23 | S3: 1936091.6
A4: 11 | B4: 10011 | C4: Chukwu Ify | D4: 10 | E4: JUNIOR | F4: SALES | G4: 132900 | H4: 33225 | I4: 13290 | J4: 16612.5 | K4: 7575.3 | L4: 4252.8 | M4: 207855.6 | N4: 2598.195 | O4: 205257.4 | P4: 2463088.9 | Q4: 31178.34 | R4: 369463.33 | S4: 2093625.5
A5: 14 | B5: 10014 | C5: Eze Nkim | D5: 11 | E5: JUNIOR | F5: SALES | G5: 142900 | H5: 35725 | I5: 14290 | J5: 17862.5 | K5: 8145.3 | L5: 4572.8 | M5: 223495.6 | N5: 2793.695 | O5: 220701.9 | P5: 2648422.9 | Q5: 33524.34 | R5: 662105.71 | S5: 1986317.1
A6: 17 | B6: 10017 | C6: Umar Habib | D6: 12 | E6: JUNIOR | F6: ACCOUNTING | G6: 152900 | H6: 38225 | I6: 15290 | J6: 19112.5 | K6: 8715.3 | L6: 4892.8 | M6: 239135.6 | N6: 2989.195 | O6: 236146.4 | P6: 2833756.9 | Q6: 35870.34 | R6: 708439.21 | S6: 2125317.6
A7: 20 | B7: 10020 | C7: Balogun Wale | D7: 8 | E7: JUNIOR | F7: ACCOUNTING | G7: 112900 | H7: 28225 | I7: 11290 | J7: 14112.5 | K7: 6435.3 | L7: 3612.8 | M7: 176575.6 | N7: 2207.195 | O7: 174368.4 | P7: 2092420.9 | Q7: 26486.34 | R7: 313863.13 | S7: 1778557.7
A8: 23 | B8: 10023 | C8: Yakubu Musa | D8: 9 | E8: JUNIOR | F8: SALES | G8: 122900 | H8: 30725 | I8: 12290 | J8: 15362.5 | K8: 7005.3 | L8: 3932.8 | M8: 192215.6 | N8: 2402.695 | O8: 189812.9 | P8: 2277754.9 | Q8: 28832.34 | R8: 341663.23 | S8: 1936091.6
A9: 26 | B9: 10026 | C9: Ogunleye Bayo | D9: 10 | E9: JUNIOR | F9: SALES | G9: 132900 | H9: 33225 | I9: 13290 | J9: 16612.5 | K9: 7575.3 | L9: 4252.8 | M9: 207855.6 | N9: 2598.195 | O9: 205257.4 | P9: 2463088.9 | Q9: 31178.34 | R9: 369463.33 | S9: 2093625.5
A10: 29 | B10: 10029 | C10: Hameerah Eniola | D10: 11 | E10: JUNIOR | F10: ACCOUNTING | G10: 142900 | H10: 35725 | I10: 14290 | J10: 17862.5 | K10: 8145.3 | L10: 4572.8 | M10: 223495.6 | N10: 2793.695 | O10: 220701.9 | P10: 2648422.9 | Q10: 33524.34 | R10: 662105.71 | S10: 1986317.1
A11: 32 | B11: 10032 | C11: Lawal Aminu | D11: 12 | E11: JUNIOR | F11: ACCOUNTING | G11: 152900 | H11: 38225 | I11: 15290 | J11: 19112.5 | K11: 8715.3 | L11: 4892.8 | M11: 239135.6 | N11: 2989.195 | O11: 236146.4 | P11: 2833756.9 | Q11: 35870.34 | R11: 708439.21 | S11: 2125317.6
A12: 35 | B12: 10035 | C12: Ahmed Sani | D12: 7 | E12: JUNIOR | F12: SALES | G12: 102900 | H12: 25725 | I12: 10290 | J12: 12862.5 | K12: 5865.3 | L12: 3292.8 | M12: 160935.6 | N12: 2011.695 | O12: 158923.9 | P12: 1907086.9 | Q12: 24140.34 | R12: 286063.03 | S12: 1621023.8
... A33: 96 | B33: 10096 | C33: Bello Rukayat | D33: 10 | E33: JUNIOR | F33: ACCOUNTING | G33: 132900 | H33: 33225 | I33: 13290 | J33: 16612.5 | K33: 7575.3 | L33: 4252.8 | M33: 207855.6 | N33: 2598.195 | O33: 205257.4 | P33: 2463088.9 | Q33: 31178.34 | R33: 369463.33 | S33: 2093625.5

Sheet CLERKS
A1: 1 | B1: 10001 | C1: Bashir Halimah | D1: 1 | E1: CLERK | F1: ACCOUNTING | G1: 70000 | H1: 17500 | I1: 7000 | J1: 8750 | K1: 3990 | L1: 2240 | M1: 109480 | N1: 1368.5 | O1: 108111.5 | P1: 1297338 | Q1: 16422 | R1: 194600.7 | S1: 1102737.3
A2: 4 | B2: 10004 | C2: Okafor Chidi | D2: 2 | E2: CLERK | F2: ENGINEERING | G2: 75000 | H2: 18750 | I2: 7500 | J2: 9375 | K2: 4275 | L2: 2400 | M2: 117300 | N2: 1466.25 | O2: 115833.75 | P2: 1390005 | Q2: 17595 | R2: 208500.75 | S2: 1181504.2
A3: 7 | B3: 10007 | C3: Etim Grace | D3: 3 | E3: CLERK | F3: ENGINEERING | G3: 80000 | H3: 20000 | I3: 8000 | J3: 10000 | K3: 4560 | L3: 2560 | M3: 125120 | N3: 1564 | O3: 123556 | P3: 1482672 | Q3: 18768 | R3: 222400.8 | S3: 1260271.2
A4: 10 | B4: 10010 | C4: Okon Peace | D4: 4 | E4: CLERK | F4: ENGINEERING | G4: 85000 | H4: 21250 | I4: 8500 | J4: 10625 | K4: 4845 | L4: 2720 | M4: 132940 | N4: 1661.75 | O4: 131278.25 | P4: 1575339 | Q4: 19941 | R4: 236300.85 | S4: 1339038.1
A5: 13 | B5: 10013 | C5: Danjuma Sadiq | D5: 5 | E5: CLERK | F5: ACCOUNTING | G5: 90000 | H5: 22500 | I5: 9000 | J5: 11250 | K5: 5130 | L5: 2880 | M5: 140760 | N5: 1759.5 | O5: 139000.5 | P5: 1668006 | Q5: 21114 | R5: 250200.9 | S5: 1417805.1
A6: 16 | B6: 10016 | C6: Ade Segun | D6: 6 | E6: CLERK | F6: ENGINEERING | G6: 95000 | H6: 23750 | I6: 9500 | J6: 11875 | K6: 5415 | L6: 3040 | M6: 148580 | N6: 1857.25 | O6: 146722.75 | P6: 1760673 | Q6: 22287 | R6: 264100.95 | S6: 1496572.1
A7: 19 | B7: 10019 | C7: Chioma Chidi | D7: 2 | E7: CLERK | F7: ENGINEERING | G7: 75000 | H7: 18750 | I7: 7500 | J7: 9375 | K7: 4275 | L7: 2400 | M7: 117300 | N7: 1466.25 | O7: 115833.75 | P7: 1390005 | Q7: 17595 | R7: 208500.75 | S7: 1181504.2
A8: 22 | B8: 10022 | C8: Nwafor Tobi | D8: 3 | E8: CLERK | F8: ENGINEERING | G8: 80000 | H8: 20000 | I8: 8000 | J8: 10000 | K8: 4560 | L8: 2560 | M8: 125120 | N8: 1564 | O8: 123556 | P8: 1482672 | Q8: 18768 | R8: 222400.8 | S8: 1260271.2
A9: 25 | B9: 10025 | C9: Aliyu Aisha | D9: 4 | E9: CLERK | F9: ACCOUNTING | G9: 85000 | H9: 21250 | I9: 8500 | J9: 10625 | K9: 4845 | L9: 2720 | M9: 132940 | N9: 1661.75 | O9: 131278.25 | P9: 1575339 | Q9: 19941 | R9: 236300.85 | S9: 1339038.1
A10: 28 | B10: 10028 | C10: Ojelabi Cecilia | D10: 5 | E10: CLERK | F10: ENGINEERING | G10: 90000 | H10: 22500 | I10: 9000 | J10: 11250 | K10: 5130 | L10: 2880 | M10: 140760 | N10: 1759.5 | O10: 139000.5 | P10: 1668006 | Q10: 21114 | R10: 250200.9 | S10: 1417805.1
A11: 31 | B11: 10031 | C11: Bala Sani | D11: 6 | E11: CLERK | F11: ENGINEERING | G11: 95000 | H11: 23750 | I11: 9500 | J11: 11875 | K11: 5415 | L11: 3040 | M11: 148580 | N11: 1857.25 | O11: 146722.75 | P11: 1760673 | Q11: 22287 | R11: 264100.95 | S11: 1496572.1
A12: 34 | B12: 10034 | C12: Ojo Titi | D12: 1 | E12: CLERK | F12: ENGINEERING | G12: 70000 | H12: 17500 | I12: 7000 | J12: 8750 | K12: 3990 | L12: 2240 | M12: 109480 | N12: 1368.5 | O12: 108111.5 | P12: 1297338 | Q12: 16422 | R12: 194600.7 | S12: 1102737.3
... A33: 95 | B33: 10095 | C33: Yakassai Sani | D33: 4 | E33: CLERK | F33: SALES | G33: 85000 | H33: 21250 | I33: 8500 | J33: 10625 | K33: 4845 | L33: 2720 | M33: 132940 | N33: 1661.75 | O33: 131278.25 | P33: 1575339 | Q33: 19941 | R33: 236300.85 | S33: 1339038.1
